Workbook
Name payable_amount: #REF!
Name payable_amount: #REF!

Sheet Title
A1: FOR CONTRACTORS & SUPPLIERS ONLY FOR PAYMENT FOR WORK OR SUPPLIES ACTUALLY MEASURED
A2: Bill Number | B2: Ninth
A3: Running or Final | B3: Final
A4: Cash Book Voucher No. and Date
A5: Name of Contractor or supplier : | B5: M/s. Shri Bajrang Construction, Padli Gujareshwar, Dungarpur
A6: Name of Work ;- | B6: Construction of Aamli Fala Bridge and Kherveda Nai Basti to Veeri Border Via Kuniya Vali Mata Road
A7: Serial No. of this bill : | B7: Ninth & Final Bill
A8: No. and date of the last bill- | B8: Not Applicable
A9: Reference to work order or Agreement : | B9: 1909 Dt. 17-07-2023
A10: Agreement No. | B10: 51/2023-24
A11: WORK ORDER AMOUNT RS. | B11: 39224443
A12: Date of written order to commence work : | B12: 45124
A13: St. date of Start : | B13: 45135
A14: St. date of completion : | B14: 45319
A15: Date of actual completion of work :
A16: Date of measurement :
A17: TENDER PREMIUM % | B17: 9.05
A18: Premium Type | B18: Below
A19: Amount Paid Vide Last Bill

Sheet Work Order
A1: Item | B1: Description | C1: Unit | D1: Quantity | E1: Rate | F1: Amount | G1: BSR
A2: 1 | B2: PART -" A" - EARTH WORK Clearing and grubbing road land including uprooting rank vegetation, grass, brush, shrubs, saplings and trees of girth upto 300mm, removal of stumps, disposal of unserviceable Material and stacking of serviceable Material upto 1000m from road boundary. (MoRTH Specification : Clause 201). BY MECHANICAL MEANS In area of Light Jungle | C2: Hect. | D2: 0.96 | E2: 17206 | F2: 16517.76
A3: 2 | B3: Earthwork in excavation for roadway in soil, including stacking / disposal of surplus Material exclusive of compensation of earth (MoRTH specification : clause 301 to 305). By Hydraulic Excavator CK-90 of 0.9 cum bucket capacity and tipper with disposal upto 1000 mtrs. | C3: cum | D3: 32746 | E3: 26 | F3: 851396
A4: 3 | B4: Earthwork in excavation in ordinary rock, including stacking / disposal of surplus Material exclusive of compensation of earth (MoRTH specification : clause 301 to 305). By Hydraulic Excavator CK-90 of 0.9 cum bucket capacity and tipper with disposal upto 1000 mtrs. | C4: cum | D4: 10291.6 | E4: 34 | F4: 349914.4
A5: 4 | B5: Earthwork in excavation for roadway in hard rock, including stacking / disposal of surplus Material exclusive of compensation of earth (MoRTH specification : clause 301 to 305). Blasting prohibited By Mechanical Means | C5: cum | D5: 3742.4 | E5: 309 | F5: 1156401.6
A6: 5 | B6: Construction of embankment with approved Material obtained from borrow-pits with all lifts and leads, transporting to site, spreading, grading to required slope and compacting by vibratory roller 8-10 tonne to meet requirement of Table 300-2 including cost of compensation for earth taken from private land with lead upto 1 km as per MoRTH Specification : Clause No. 305. | C6: cum | D6: 13840 | E6: 52 | F6: 719680
A7: 6 | B7: Construction of embankment with approved Materials deposited at site from roadway cutting and excavation from drain and foundation of other structures graded and compacted by vibratory roller 8-10 tonne to meet requirement of Tale 300-2 as per MoRTH specification : Clause No. 305 | C7: cum | D7: 46780 | E7: 19 | F7: 888820
A8: 7 | B8: Construction of sub-grade and earthen shoulders with approved Material obtained from borrow-pits with all lifts and leads, transporting to site, spreading, grading to require slope and compacted by vibratory roller 8-10 tonne to meet requirement of Table 300-2 as per MoRTH specification : Clause No. 305. | C8: cum | D8: 3966.02 | E8: 54 | F8: 214165.08
A9: 8 | B9: PART -" B" - WBM & Hard Shoulder Providing, laying and spreading of granular sub-base by providing coarse graded Material, spreading in uniform layers with motor grader on prepared surface mixing by mix in place method with rotavator at OMC, and compacting with vibratory roller to achieve the desired density, complete as per MoRTH Specification : clause No. 401. Grading-II | C9: Cum | D9: 2478.6 | E9: 848 | F9: 2101852.8
A10: 9 | B10: Providing, laying, spreading and compacting crushed graded stone aggregate as per Table 400-10 & 400.11 to Wet Mix Macadam specifications including premixing the Material with water to OMC in mechanical mixer (Pug mill) as per design mix, carriage of mixed Material by tipper to site laying in uniform layers, with motor grader/F.E. loader/Paver Finisher, in sub- base/base course on a well prepared under base and compacting with Vibratory Roller to achieve the desired density including lighting, guarding, barricading and maintenance of Driversion etc. (MoRTH specification : Clause 406). with all lead & lift By mechanical means | C10: Cum | D10: 2295 | E10: 1056 | F10: 2423520
A11: 10 | B11: PART -" C" - B.T. Work Providing and applying primer coat over prepared surface of granular base with bitumen emulsion as per IS:8887 & manufacturer’s specifications @6 kg/10 sqm with a self propelled or towed bitumen pressure sprayer equipped for spraying the Material uniformly at specified rates and temperatures (including cleaning of road surface) as per MoRTH specification : Cl. 502, 112 | C11: Sqm. | D11: 15300 | E11: 25.26 | F11: 386478
A12: 11 | B12: Providing and laying open graded premix carpet 20mm thick (compacted), on prepared surface in a single course as wearing course, composed of specified graded crushed aggregates as per Table 500-23, heating bituminous binder @ 14.6 kg/10 sqm and aggregates in Hot Mix Plant (including cost of anti-stripping compound, wherever required), transporting the mixed Material with tipper and laying with paver finisher to the required level and grade, rolling with power roller, 8-10 tonne, but excluding cost of tack coat and seal coat with lead for mix of Material 1 km (MoRTH specification : clause 510, 112) In Hot Mix Plant 40-60 TPH, including loading of aggregates with F.E. loader bitumen VG30 grade | C12: Sqm. | D12: 15300 | E12: 94 | F12: 1438200
A13: 12 | B13: Providing and applying Premixed Seal Coat type “B” comprising of thin application of fine aggregate (0.06 cum per 10 sqm) premix with (6.8 kg per 10 sqm) bitumen binder (including cost of anti-stripping compound, wherever required) in mini hot mix plant 6-10 TPH, and laying with paver finisher and rolling with power roller 8-10 tonne, including all lead of mix Material (MoRTH specification : clause 511). Bitumen VG30 grade | C13: Sqm. | D13: 15300 | E13: 31 | F13: 474300
... A21: 20 | B21: Flexible Crash Barrier, Wire Rope Safety Barrier Providing and erecting a wire rope safety barrier with vertical posts of medium weight RS Joist (ISMB series) 100 mm x 75 mm (11.50 kg/m), 1.50 m long 0.85 m above ground and 0.65 m below ground level, split at the bottom for better grip, embedded in M 15 grade cement concrete 450 x 450 x 450 mm, 1.50 m center to center and with 4 horizontal steel wire rope 40 mm dia and anchored at terminal posts 15 m apart. Terminal post to be embedded in M 15 grade cement concrete foundation 2400 x 450 x 900 mm (depth), strengthened by a strut of RS joist 100 x 75 mm, 2 m long at 450 inclination and a tie 100 x 8 mm, 1.50 m long at the bottom, all embedded in foundation concrete as per approved design and drawing, rate excluding excavation and cement concrete. | C21: Running metre | D21: 15 | E21: 1768 | F21: 26520
A22: 21 | B22: Part ''E'' CD Work Earthwork in excavation for foundation of structure complete with all lift, dewatering, shoring and shuttering etc. including refilling of trenches in 250 mm layer, ramming, watering and disposal of surplus soil within a lead of 1000 meters, as per drawing and technical Earth in excavation for foundation of specification. [MoRTH Specification : Clause 304]. n ordinary soil [MoRTH Specification : clause 301] BY MECHANICAL MEANS Depth upto 3m
A23: 21.01 | B23: 1000mm dia HP 1 Row | C23: cum | D23: 681.84 | E23: 57 | F23: 38864.88
A24: 21.02 | B24: 1000mm dia HP 2 Row | C24: cum | D24: 450.8 | E24: 57 | F24: 25695.6
A25: 21.03 | B25: RCC Bridge | C25: cum | D25: 617.016 | E25: 57 | F25: 35169.91
A26: 21.04 | B26: Syphon | C26: cum | D26: 95.84 | E26: 57 | F26: 5462.88
A27: 21.05 | B27: Retaining wall | C27: cum | D27: 1680 | E27: 57 | F27: 95760
A28: 21.06 | B28: VCW | C28: cum | D28: 1252.5 | E28: 57 | F28: 71392.5
A29: 22 | B29: Earthwork in excavation for foundation of structure complete with all lift, dewatering, shoring and shuttering etc. including refilling of trenches in 250 mm layer, ramming, watering and disposal of surplus soil within a lead of 1000 meters, as per drawing and technical Earth in excavation for foundation of specification. [MoRTH Specification : Clause 304].In Ordinary/Soft rock (not requiring blasting) [MoRTH Specification : Clause 301] BY MECHANICAL MEANS
A30: 22.01 | B30: RCC Bridge | C30: cum | D30: 666.27 | E30: 83 | F30: 55300.41
A31: 23 | B31: Earthwork in excavation for foundation of structure complete with all lift, dewatering, shoring and shuttering etc. including refilling of trenches in 250 mm layer, ramming, watering and disposal of surplus soil within a lead of 1000 meters, as per drawing and technical Earth in excavation for foundation of specification. [MoRTH Specification : Clause 304]. In Hard Rock [MoRTH Specification : Clause 301, 302, 303]. Blasting Prohibited
A32: 23.01 | B32: RCC Bridge | C32: cum | D32: 456.27 | E32: 670 | F32: 305700.9
A33: 24 | B33: Plain Cement Concrete 1:3:6 with 40mm nominal mix in foundation with crushed stone aggregate 40mm nominal size mechanically mixed, placed in foundation and compacted by vibrator including curing for 14 days. (MoRTH specification clause : 2100)
A34: 24.01 | B34: 1000mm dia HP 1 Row | C34: cum | D34: 46.44 | E34: 3038 | F34: 141084.72
A35: 24.02 | B35: 1000mm dia HP 2 Row | C35: cum | D35: 26.8 | E35: 3038 | F35: 81418.4
A36: 24.03 | B36: Retaining wall | C36: cum | D36: 167.99 | E36: 3038 | F36: 510353.62
A37: 24.04 | B37: VCW | C37: cum | D37: 80.7 | E37: 3038 | F37: 245166.6
A38: 25 | B38: Structural cement concrete (Design Mix) in open foundations, with form work, at any level. Cement concrete for plain/reinforced concrete in open foundations as per drawing and technical specification. [MoRTH Specification : Section 1700 & 1500]. With 20mm nominal size aggregate P.C.C. M-20 grade
A39: 25.01 | B39: RCC Bridge | C39: cum | D39: 74.43 | E39: 4017 | F39: 298985.31
A40: 26 | B40: Structural cement concrete (Design Mix) in open foundations, with form work, at any level. Cement concrete for plain/reinforced concrete in open foundations as per drawing and technical specification. [MoRTH Specification : Section 1700 & 1500]. With 20mm nominal size aggregate R.C.C. M-25 grade
A41: 26.01 | B41: RCC Bridge | C41: cum | D41: 465.18 | E41: 4341 | F41: 2019346.4
A42: 27 | B42: Providing and laying Plain Cement Concrete M-15 mix with stone aggregate 20mm nominal size mechanically mixed and vibrated in foundation upto a depth of 1.50 below ground level and or 1.50mtr. above ground/bed level.
A43: 27.01 | B43: 1000mm dia HP 1 Row | C43: cum | D43: 409.5 | E43: 3666 | F43: 1501227
A44: 27.02 | B44: 1000mm dia HP 2 Row | C44: cum | D44: 225.36 | E44: 3666 | F44: 826169.76
A45: 27.03 | B45: Syphon | C45: cum | D45: 41.481 | E45: 3666 | F45: 152069.35
A46: 27.04 | B46: Retaining wall | C46: cum | D46: 1531.25 | E46: 3666 | F46: 5613562.5
A47: 27.05 | B47: VCW | C47: cum | D47: 629.53 | E47: 3666 | F47: 2307857
...

Sheet Bill Quantity
A1: Item | B1: Description | C1: Unit | D1: Quantity | E1: Rate | F1: Amount | G1: BSR
A2: 1 | B2: PART -" A" - EARTH WORK Clearing and grubbing road land including uprooting rank vegetation, grass, brush, shrubs, saplings and trees of girth upto 300mm, removal of stumps, disposal of unserviceable Material and stacking of serviceable Material upto 1000m from road boundary. (MoRTH Specification : Clause 201). BY MECHANICAL MEANS In area of Light Jungle | C2: Hect. | D2: 0.96 | E2: 17206 | F2: =IF(D2,D2*E2," ") -> 16517.76
A3: 2 | B3: Earthwork in excavation for roadway in soil, including stacking / disposal of surplus Material exclusive of compensation of earth (MoRTH specification : clause 301 to 305). By Hydraulic Excavator CK-90 of 0.9 cum bucket capacity and tipper with disposal upto 1000 mtrs. | C3: cum | D3: 47317.97 | E3: 26 | F3: =IF(D3,D3*E3," ") -> 1230267.2
A4: 3 | B4: Earthwork in excavation in ordinary rock, including stacking / disposal of surplus Material exclusive of compensation of earth (MoRTH specification : clause 301 to 305). By Hydraulic Excavator CK-90 of 0.9 cum bucket capacity and tipper with disposal upto 1000 mtrs. | C4: cum | D4: 15072.05 | E4: 34 | F4: =IF(D4,D4*E4," ") -> 512449.7
A5: 4 | B5: Earthwork in excavation for roadway in hard rock, including stacking / disposal of surplus Material exclusive of compensation of earth (MoRTH specification : clause 301 to 305). Blasting prohibited By Mechanical Means | C5: cum | D5: 5579.92 | E5: 309 | F5: =IF(D5,D5*E5," ") -> 1724195.3
A6: 5 | B6: Construction of embankment with approved Material obtained from borrow-pits with all lifts and leads, transporting to site, spreading, grading to required slope and compacting by vibratory roller 8-10 tonne to meet requirement of Table 300-2 including cost of compensation for earth taken from private land with lead upto 1 km as per MoRTH Specification : Clause No. 305. | C6: cum | D6: 19798.12 | E6: 52 | F6: =IF(D6,D6*E6," ") -> 1029502.2
A7: 6 | B7: Construction of embankment with approved Materials deposited at site from roadway cutting and excavation from drain and foundation of other structures graded and compacted by vibratory roller 8-10 tonne to meet requirement of Tale 300-2 as per MoRTH specification : Clause No. 305 | C7: cum | D7: 68906.94 | E7: 19 | F7: =IF(D7,D7*E7," ") -> 1309231.9
A8: 7 | B8: Construction of sub-grade and earthen shoulders with approved Material obtained from borrow-pits with all lifts and leads, transporting to site, spreading, grading to require slope and compacted by vibratory roller 8-10 tonne to meet requirement of Table 300-2 as per MoRTH specification : Clause No. 305. | C8: cum | D8: 3966.02 | E8: 54 | F8: =IF(D8,D8*E8," ") -> 214165.08
A9: 8 | B9: PART -" B" - WBM & Hard Shoulder Providing, laying and spreading of granular sub-base by providing coarse graded Material, spreading in uniform layers with motor grader on prepared surface mixing by mix in place method with rotavator at OMC, and compacting with vibratory roller to achieve the desired density, complete as per MoRTH Specification : clause No. 401. Grading-II | C9: Cum | D9: 2478.6 | E9: 848 | F9: =IF(D9,D9*E9," ") -> 2101852.8
A10: 9 | B10: Providing, laying, spreading and compacting crushed graded stone aggregate as per Table 400-10 & 400.11 to Wet Mix Macadam specifications including premixing the Material with water to OMC in mechanical mixer (Pug mill) as per design mix, carriage of mixed Material by tipper to site laying in uniform layers, with motor grader/F.E. loader/Paver Finisher, in sub- base/base course on a well prepared under base and compacting with Vibratory Roller to achieve the desired density including lighting, guarding, barricading and maintenance of Driversion etc. (MoRTH specification : Clause 406). with all lead & lift By mechanical means | C10: Cum | D10: 2295 | E10: 1056 | F10: =IF(D10,D10*E10," ") -> 2423520
A11: 10 | B11: PART -" C" - B.T. Work Providing and applying primer coat over prepared surface of granular base with bitumen emulsion as per IS:8887 & manufacturer’s specifications @6 kg/10 sqm with a self propelled or towed bitumen pressure sprayer equipped for spraying the Material uniformly at specified rates and temperatures (including cleaning of road surface) as per MoRTH specification : Cl. 502, 112 | C11: Sqm. | D11: 15300 | E11: 25.26 | F11: =IF(D11,D11*E11," ") -> 386478
A12: 11 | B12: Providing and laying open graded premix carpet 20mm thick (compacted), on prepared surface in a single course as wearing course, composed of specified graded crushed aggregates as per Table 500-23, heating bituminous binder @ 14.6 kg/10 sqm and aggregates in Hot Mix Plant (including cost of anti-stripping compound, wherever required), transporting the mixed Material with tipper and laying with paver finisher to the required level and grade, rolling with power roller, 8-10 tonne, but excluding cost of tack coat and seal coat with lead for mix of Material 1 km (MoRTH specification : clause 510, 112) In Hot Mix Plant 40-60 TPH, including loading of aggregates with F.E. loader bitumen VG30 grade | C12: Sqm. | D12: 15300 | E12: 94 | F12: =IF(D12,D12*E12," ") -> 1438200
A13: 12 | B13: Providing and applying Premixed Seal Coat type “B” comprising of thin application of fine aggregate (0.06 cum per 10 sqm) premix with (6.8 kg per 10 sqm) bitumen binder (including cost of anti-stripping compound, wherever required) in mini hot mix plant 6-10 TPH, and laying with paver finisher and rolling with power roller 8-10 tonne, including all lead of mix Material (MoRTH specification : clause 511). Bitumen VG30 grade | C13: Sqm. | D13: 15300 | E13: 31 | F13: =IF(D13,D13*E13," ") -> 474300
... A21: 20 | B21: Flexible Crash Barrier, Wire Rope Safety Barrier Providing and erecting a wire rope safety barrier with vertical posts of medium weight RS Joist (ISMB series) 100 mm x 75 mm (11.50 kg/m), 1.50 m long 0.85 m above ground and 0.65 m below ground level, split at the bottom for better grip, embedded in M 15 grade cement concrete 450 x 450 x 450 mm, 1.50 m center to center and with 4 horizontal steel wire rope 40 mm dia and anchored at terminal posts 15 m apart. Terminal post to be embedded in M 15 grade cement concrete foundation 2400 x 450 x 900 mm (depth), strengthened by a strut of RS joist 100 x 75 mm, 2 m long at 450 inclination and a tie 100 x 8 mm, 1.50 m long at the bottom, all embedded in foundation concrete as per approved design and drawing, rate excluding excavation and cement concrete. | C21: Running metre | D21: 15 | E21: 1768 | F21: =IF(D21,D21*E21," ") -> 26520
A22: 21 | B22: Part ''E'' CD Work Earthwork in excavation for foundation of structure complete with all lift, dewatering, shoring and shuttering etc. including refilling of trenches in 250 mm layer, ramming, watering and disposal of surplus soil within a lead of 1000 meters, as per drawing and technical Earth in excavation for foundation of specification. [MoRTH Specification : Clause 304]. n ordinary soil [MoRTH Specification : clause 301] BY MECHANICAL MEANS Depth upto 3m | F22: =IF(D22,D22*E22," ")
A23: 21.01 | B23: 1000mm dia HP 1 Row | C23: cum | D23: 681.84 | E23: 57 | F23: =IF(D23,D23*E23," ") -> 38864.88
A24: 21.02 | B24: 1000mm dia HP 2 Row | C24: cum | D24: 450.8 | E24: 57 | F24: =IF(D24,D24*E24," ") -> 25695.6
A25: 21.03 | B25: RCC Bridge | C25: cum | D25: 618.58 | E25: 57 | F25: =IF(D25,D25*E25," ") -> 35259.06
A26: 21.04 | B26: Syphon | C26: cum | D26: 95.84 | E26: 57 | F26: =IF(D26,D26*E26," ") -> 5462.88
A27: 21.05 | B27: Retaining wall | C27: cum | D27: 1680 | E27: 57 | F27: =IF(D27,D27*E27," ") -> 95760
A28: 21.06 | B28: VCW | C28: cum | D28: 1252.5 | E28: 57 | F28: =IF(D28,D28*E28," ") -> 71392.5
A29: 22 | B29: Earthwork in excavation for foundation of structure complete with all lift, dewatering, shoring and shuttering etc. including refilling of trenches in 250 mm layer, ramming, watering and disposal of surplus soil within a lead of 1000 meters, as per drawing and technical Earth in excavation for foundation of specification. [MoRTH Specification : Clause 304].In Ordinary/Soft rock (not requiring blasting) [MoRTH Specification : Clause 301] BY MECHANICAL MEANS | F29: =IF(D29,D29*E29," ")
A30: 22.01 | B30: RCC Bridge | C30: cum | D30: 990.08 | E30: 83 | F30: =IF(D30,D30*E30," ") -> 82176.64
A31: 23 | B31: Earthwork in excavation for foundation of structure complete with all lift, dewatering, shoring and shuttering etc. including refilling of trenches in 250 mm layer, ramming, watering and disposal of surplus soil within a lead of 1000 meters, as per drawing and technical Earth in excavation for foundation of specification. [MoRTH Specification : Clause 304]. In Hard Rock [MoRTH Specification : Clause 301, 302, 303]. Blasting Prohibited | F31: =IF(D31,D31*E31," ")
A32: 23.01 | B32: RCC Bridge | C32: cum | D32: 1088.31 | E32: 670 | F32: =IF(D32,D32*E32," ") -> 729167.7
A33: 24 | B33: Plain Cement Concrete 1:3:6 with 40mm nominal mix in foundation with crushed stone aggregate 40mm nominal size mechanically mixed, placed in foundation and compacted by vibrator including curing for 14 days. (MoRTH specification clause : 2100) | F33: =IF(D33,D33*E33," ")
A34: 24.01 | B34: 1000mm dia HP 1 Row | C34: cum | D34: 46.44 | E34: 3038 | F34: =IF(D34,D34*E34," ") -> 141084.72
A35: 24.02 | B35: 1000mm dia HP 2 Row | C35: cum | D35: 26.8 | E35: 3038 | F35: =IF(D35,D35*E35," ") -> 81418.4
A36: 24.03 | B36: Retaining wall | C36: cum | D36: 167.99 | E36: 3038 | F36: =IF(D36,D36*E36," ") -> 510353.62
A37: 24.04 | B37: VCW | C37: cum | D37: 80.7 | E37: 3038 | F37: =IF(D37,D37*E37," ") -> 245166.6
A38: 25 | B38: Structural cement concrete (Design Mix) in open foundations, with form work, at any level. Cement concrete for plain/reinforced concrete in open foundations as per drawing and technical specification. [MoRTH Specification : Section 1700 & 1500]. With 20mm nominal size aggregate P.C.C. M-20 grade | F38: =IF(D38,D38*E38," ")
A39: 25.01 | B39: RCC Bridge | C39: cum | D39: 114.44 | E39: 4017 | F39: =IF(D39,D39*E39," ") -> 459705.48
A40: 26 | B40: Structural cement concrete (Design Mix) in open foundations, with form work, at any level. Cement concrete for plain/reinforced concrete in open foundations as per drawing and technical specification. [MoRTH Specification : Section 1700 & 1500]. With 20mm nominal size aggregate R.C.C. M-25 grade | F40: =IF(D40,D40*E40," ")
A41: 26.01 | B41: RCC Bridge | C41: cum | D41: 961.61 | E41: 4341 | F41: =IF(D41,D41*E41," ") -> 4174349
A42: 27 | B42: Providing and laying Plain Cement Concrete M-15 mix with stone aggregate 20mm nominal size mechanically mixed and vibrated in foundation upto a depth of 1.50 below ground level and or 1.50mtr. above ground/bed level. | F42: =IF(D42,D42*E42," ")
A43: 27.01 | B43: 1000mm dia HP 1 Row | C43: cum | D43: 409.5 | E43: 3666 | F43: =IF(D43,D43*E43," ") -> 1501227
A44: 27.02 | B44: 1000mm dia HP 2 Row | C44: cum | D44: 225.36 | E44: 3666 | F44: =IF(D44,D44*E44," ") -> 826169.76
A45: 27.03 | B45: Syphon | C45: cum | D45: 41.481 | E45: 3666 | F45: =IF(D45,D45*E45," ") -> 152069.35
A46: 27.04 | B46: Retaining wall | C46: cum | D46: 1531.25 | E46: 3666 | F46: =IF(D46,D46*E46," ") -> 5613562.5
A47: 27.05 | B47: VCW | C47: cum | D47: 629.53 | E47: 3666 | F47: =IF(D47,D47*E47," ") -> 2307857
...

Sheet Extra Items
D1: EXTRA ITEM SLIP
A2: Name of Work :- | C2: =Title!B6 -> Construction of Aamli Fala Bridge and Kherveda Nai Basti to Veeri Border Via Kuniya Vali Mata Road
A3: Name of Contractor or supplier : | C3: =Title!B5 -> M/s. Shri Bajrang Construction, Padli Gujareshwar, Dungarpur
A4: Reference to work order or Agreement : | C4: =Title!B9 -> 1909 Dt. 17-07-2023
A6: S.No. | B6: Ref. BSR No. | C6: Particulars | D6: Qty. | E6: unit | F6: Rate | G6: Amount | H6: Remarks
A7: E-01 | D7: 0 | E7: Each | F7: 5075 | G7: =IF(ISBLANK(D7),"",ROUND(D7*F7,0)) -> 0
A8: E-02 | D8: 0 | E8: Each | F8: 107 | G8: =IF(ISBLANK(D8),"",ROUND(D8*F8,0)) -> 0
A9: E-03 | D9: 0 | E9: Each | F9: 176 | G9: =IF(ISBLANK(D9),"",ROUND(D9*F9,0)) -> 0
A10: E-04 | D10: 0 | E10: Each | F10: 345 | G10: =IF(ISBLANK(D10),"",ROUND(D10*F10,0)) -> 0
A11: E-05 | D11: 0 | E11: Each | F11: 107 | G11: =IF(ISBLANK(D11),"",ROUND(D11*F11,0)) -> 0
A12: E-06 | D12: 0 | E12: Each | F12: 176 | G12: =IF(ISBLANK(D12),"",ROUND(D12*F12,0)) -> 0
C13: Total | G13: =SUM(G7:G12) -> 0
C14: Add Tender Premium | D14: % | E14: =Title!B17 -> 9.05 | F14: =Title!B18 -> Below | G14: =IF(F14 > 0, IF(F14 = "above", ROUND(G13 * E14 / 100, 0), IF(F14 = "below", -ROUND(G13 * E14 / 100, 0), IF(F14 = 0, 0, 0)))) -> 0
C15: Grand Total | G15: =G13+G14 -> 0
